2022-09-25 17:43:54.558056: I tensorflow/core/util/util.cc:169] oneDNN custom operations are on. You may see slightly different numerical results due to floating-point round-off errors from different computation orders. To turn them off, set the environment variable `TF_ENABLE_ONEDNN_OPTS=0`.
2022-09-25 17:43:54.563308: W tensorflow/stream_executor/platform/default/dso_loader.cc:64] Could not load dynamic library 'libcudart.so.11.0'; dlerror: libcudart.so.11.0: cannot open shared object file: No such file or directory; LD_LIBRARY_PATH: /software/cudnn-8.3.1-el8-x86_64/lib64
2022-09-25 17:43:54.563334: I tensorflow/stream_executor/cuda/cudart_stub.cc:29] Ignore above cudart dlerror if you do not have a GPU set up on your machine.
2022-09-25 17:43:59.356261: W tensorflow/stream_executor/platform/default/dso_loader.cc:64] Could not load dynamic library 'libcuda.so.1'; dlerror: libcuda.so.1: cannot open shared object file: No such file or directory; LD_LIBRARY_PATH: /software/cudnn-8.3.1-el8-x86_64/lib64
2022-09-25 17:43:59.356299: W tensorflow/stream_executor/cuda/cuda_driver.cc:269] failed call to cuInit: UNKNOWN ERROR (303)
2022-09-25 17:43:59.356319: I tensorflow/stream_executor/cuda/cuda_diagnostics.cc:156] kernel driver does not appear to be running on this host (midway3-0035.rcc.local): /proc/driver/nvidia/version does not exist
2022-09-25 17:43:59.356722: I tensorflow/core/platform/cpu_feature_guard.cc:193] This TensorFlow binary is optimized with oneAPI Deep Neural Network Library (oneDNN) to use the following CPU instructions in performance-critical operations:  AVX2 AVX512F AVX512_VNNI FMA
To enable them in other operations, rebuild TensorFlow with the appropriate compiler flags.
Traceback (most recent call last):
  File "standard_moments.py", line 311, in <module>
    dVtilde_logQ_MFR            = np.genfromtxt(mfrSuite_resdir + '/dlogQ_dH_final.dat').reshape(-1,1)
  File "/software/python-anaconda-2021.05-el8-x86_64/lib/python3.8/site-packages/numpy/lib/npyio.py", line 1791, in genfromtxt
    fid = np.lib._datasource.open(fname, 'rt', encoding=encoding)
  File "/software/python-anaconda-2021.05-el8-x86_64/lib/python3.8/site-packages/numpy/lib/_datasource.py", line 194, in open
    return ds.open(path, mode, encoding=encoding, newline=newline)
  File "/software/python-anaconda-2021.05-el8-x86_64/lib/python3.8/site-packages/numpy/lib/_datasource.py", line 531, in open
    raise IOError("%s not found." % path)
OSError: /project/lhansen/mfrSuite_solution/WZVtilde_sigma_K_0040_sigma_Z_0014_sigma_V_0000_sigma_Vtilde_0100/chiUnderline_0200_a_e_0150_a_h_0050_gamma_e_1000_gamma_h_3000_psi_e_1500_psi_h_1500//dlogQ_dH_final.dat not found.
